sqlalchemy.exc.TimeoutError: QueuePool limit of size 5 overflow 2 reached, connection timed out, timeout 30.00 (Background on this error at: https://sqlalche.me/e/20/3o7r)
Traceback:
File "/home/runner/workspace/.pythonlibs/lib/python3.11/site-packages/streamlit/runtime/scriptrunner/exec_code.py", line 121, in exec_func_with_error_handling
    result = func()
             ^^^^^^
File "/home/runner/workspace/.pythonlibs/lib/python3.11/site-packages/streamlit/runtime/scriptrunner/script_runner.py", line 593, in code_to_exec
    exec(code, module.__dict__)
File "/home/runner/workspace/app.py", line 236, in <module>
    ).first() is not None
      ^^^^^^^
File "/home/runner/workspace/.pythonlibs/lib/python3.11/site-packages/sqlalchemy/orm/query.py", line 2759, in first
    return self.limit(1)._iter().first()  # type: ignore
           ^^^^^^^^^^^^^^^^^^^^^
File "/home/runner/workspace/.pythonlibs/lib/python3.11/site-packages/sqlalchemy/orm/query.py", line 2858, in _iter
    result: Union[ScalarResult[_T], Result[_T]] = self.session.execute(
                                                  ^^^^^^^^^^^^^^^^^^^^^
File "/home/runner/workspace/.pythonlibs/lib/python3.11/site-packages/sqlalchemy/orm/session.py", line 2365, in execute
    return self._execute_internal(
           ^^^^^^^^^^^^^^^^^^^^^^^
File "/home/runner/workspace/.pythonlibs/lib/python3.11/site-packages/sqlalchemy/orm/session.py", line 2241, in _execute_internal
    conn = self._connection_for_bind(bind)
           ^^^^^^^^^^^^^^^^^^^^^^^^^^^^^^^
File "/home/runner/workspace/.pythonlibs/lib/python3.11/site-packages/sqlalchemy/orm/session.py", line 2110, in _connection_for_bind
    return trans._connection_for_bind(engine, execution_options)
           ^^^^^^^^^^^^^^^^^^^^^^^^^^^^^^^^^^^^^^^^^^^^^^^^^^^^^
File "<string>", line 2, in _connection_for_bind
File "/home/runner/workspace/.pythonlibs/lib/python3.11/site-packages/sqlalchemy/orm/state_changes.py", line 139, in _go
    ret_value = fn(self, *arg, **kw)
                ^^^^^^^^^^^^^^^^^^^^
File "/home/runner/workspace/.pythonlibs/lib/python3.11/site-packages/sqlalchemy/orm/session.py", line 1189, in _connection_for_bind
    conn = bind.connect()
           ^^^^^^^^^^^^^^
File "/home/runner/workspace/.pythonlibs/lib/python3.11/site-packages/sqlalchemy/engine/base.py", line 3274, in connect
    return self._connection_cls(self)
           ^^^^^^^^^^^^^^^^^^^^^^^^^^
File "/home/runner/workspace/.pythonlibs/lib/python3.11/site-packages/sqlalchemy/engine/base.py", line 146, in __init__
    self._dbapi_connection = engine.raw_connection()
                             ^^^^^^^^^^^^^^^^^^^^^^^
File "/home/runner/workspace/.pythonlibs/lib/python3.11/site-packages/sqlalchemy/engine/base.py", line 3298, in raw_connection
    return self.pool.connect()
           ^^^^^^^^^^^^^^^^^^^
File "/home/runner/workspace/.pythonlibs/lib/python3.11/site-packages/sqlalchemy/pool/base.py", line 449, in connect
    return _ConnectionFairy._checkout(self)
           ^^^^^^^^^^^^^^^^^^^^^^^^^^^^^^^^
File "/home/runner/workspace/.pythonlibs/lib/python3.11/site-packages/sqlalchemy/pool/base.py", line 1264, in _checkout
    fairy = _ConnectionRecord.checkout(pool)
            ^^^^^^^^^^^^^^^^^^^^^^^^^^^^^^^^
File "/home/runner/workspace/.pythonlibs/lib/python3.11/site-packages/sqlalchemy/pool/base.py", line 713, in checkout
    rec = pool._do_get()
          ^^^^^^^^^^^^^^
File "/home/runner/workspace/.pythonlibs/lib/python3.11/site-packages/sqlalchemy/pool/impl.py", line 168, in _do_get
    raise exc.TimeoutError(